2020-01-13 12:10:02,100 INFO: Web CIR startup [in C:\Reports\Applications\web_CIR\app\__init__.py:47]
2020-01-13 12:12:36,535 INFO: Web CIR startup [in C:\Reports\Applications\web_CIR\app\__init__.py:47]
2020-01-13 12:15:24,755 INFO: Web CIR startup [in C:\Reports\Applications\web_CIR\app\__init__.py:47]
2020-01-13 12:16:16,556 ERROR: Exception on /CIR [POST] [in c:\reports\applications\web_cir\venv\lib\site-packages\flask\app.py:1891]
Traceback (most recent call last):
  File "c:\reports\applications\web_cir\venv\lib\site-packages\sqlalchemy\engine\base.py", line 1246, in _execute_context
    cursor, statement, parameters, context
  File "c:\reports\applications\web_cir\venv\lib\site-packages\sqlalchemy\engine\default.py", line 581, in do_execute
    cursor.execute(statement, parameters)
sqlite3.OperationalError: database is locked

The above exception was the direct cause of the following exception:

Traceback (most recent call last):
  File "c:\reports\applications\web_cir\venv\lib\site-packages\flask\app.py", line 2446, in wsgi_app
    response = self.full_dispatch_request()
  File "c:\reports\applications\web_cir\venv\lib\site-packages\flask\app.py", line 1951, in full_dispatch_request
    rv = self.handle_user_exception(e)
  File "c:\reports\applications\web_cir\venv\lib\site-packages\flask\app.py", line 1820, in handle_user_exception
    reraise(exc_type, exc_value, tb)
  File "c:\reports\applications\web_cir\venv\lib\site-packages\flask\_compat.py", line 39, in reraise
    raise value
  File "c:\reports\applications\web_cir\venv\lib\site-packages\flask\app.py", line 1949, in full_dispatch_request
    rv = self.dispatch_request()
  File "c:\reports\applications\web_cir\venv\lib\site-packages\flask\app.py", line 1935, in dispatch_request
    return self.view_functions[rule.endpoint](**req.view_args)
  File "c:\reports\applications\web_cir\venv\lib\site-packages\flask_login\utils.py", line 261, in decorated_view
    return func(*args, **kwargs)
  File "C:\Reports\Applications\web_CIR\app\routes.py", line 58, in CIR
    db.session.commit()
  File "c:\reports\applications\web_cir\venv\lib\site-packages\sqlalchemy\orm\scoping.py", line 162, in do
    return getattr(self.registry(), name)(*args, **kwargs)
  File "c:\reports\applications\web_cir\venv\lib\site-packages\sqlalchemy\orm\session.py", line 1036, in commit
    self.transaction.commit()
  File "c:\reports\applications\web_cir\venv\lib\site-packages\sqlalchemy\orm\session.py", line 503, in commit
    self._prepare_impl()
  File "c:\reports\applications\web_cir\venv\lib\site-packages\sqlalchemy\orm\session.py", line 482, in _prepare_impl
    self.session.flush()
  File "c:\reports\applications\web_cir\venv\lib\site-packages\sqlalchemy\orm\session.py", line 2479, in flush
    self._flush(objects)
  File "c:\reports\applications\web_cir\venv\lib\site-packages\sqlalchemy\orm\session.py", line 2617, in _flush
    transaction.rollback(_capture_exception=True)
  File "c:\reports\applications\web_cir\venv\lib\site-packages\sqlalchemy\util\langhelpers.py", line 68, in __exit__
    compat.reraise(exc_type, exc_value, exc_tb)
  File "c:\reports\applications\web_cir\venv\lib\site-packages\sqlalchemy\util\compat.py", line 153, in reraise
    raise value
  File "c:\reports\applications\web_cir\venv\lib\site-packages\sqlalchemy\orm\session.py", line 2577, in _flush
    flush_context.execute()
  File "c:\reports\applications\web_cir\venv\lib\site-packages\sqlalchemy\orm\unitofwork.py", line 422, in execute
    rec.execute(self)
  File "c:\reports\applications\web_cir\venv\lib\site-packages\sqlalchemy\orm\unitofwork.py", line 589, in execute
    uow,
  File "c:\reports\applications\web_cir\venv\lib\site-packages\sqlalchemy\orm\persistence.py", line 245, in save_obj
    insert,
  File "c:\reports\applications\web_cir\venv\lib\site-packages\sqlalchemy\orm\persistence.py", line 1137, in _emit_insert_statements
    statement, params
  File "c:\reports\applications\web_cir\venv\lib\site-packages\sqlalchemy\engine\base.py", line 982, in execute
    return meth(self, multiparams, params)
  File "c:\reports\applications\web_cir\venv\lib\site-packages\sqlalchemy\sql\elements.py", line 287, in _execute_on_connection
    return connection._execute_clauseelement(self, multiparams, params)
  File "c:\reports\applications\web_cir\venv\lib\site-packages\sqlalchemy\engine\base.py", line 1101, in _execute_clauseelement
    distilled_params,
  File "c:\reports\applications\web_cir\venv\lib\site-packages\sqlalchemy\engine\base.py", line 1250, in _execute_context
    e, statement, parameters, cursor, context
  File "c:\reports\applications\web_cir\venv\lib\site-packages\sqlalchemy\engine\base.py", line 1476, in _handle_dbapi_exception
    util.raise_from_cause(sqlalchemy_exception, exc_info)
  File "c:\reports\applications\web_cir\venv\lib\site-packages\sqlalchemy\util\compat.py", line 398, in raise_from_cause
    reraise(type(exception), exception, tb=exc_tb, cause=cause)
  File "c:\reports\applications\web_cir\venv\lib\site-packages\sqlalchemy\util\compat.py", line 152, in reraise
    raise value.with_traceback(tb)
  File "c:\reports\applications\web_cir\venv\lib\site-packages\sqlalchemy\engine\base.py", line 1246, in _execute_context
    cursor, statement, parameters, context
  File "c:\reports\applications\web_cir\venv\lib\site-packages\sqlalchemy\engine\default.py", line 581, in do_execute
    cursor.execute(statement, parameters)
sqlalchemy.exc.OperationalError: (sqlite3.OperationalError) database is locked
[SQL: INSERT INTO ci_report (date_inserted, author_id, incident_datetime, school_name, incident_type, narrative, comments, phys_restraint, police, phys_harm, fire_rescue, dcyf, risk_assessment, cteam_response) VALUES (?, ?, ?, ?, ?, ?, ?, ?, ?, ?, ?, ?, ?, ?)]
[parameters: ('2020-01-13 17:16:11.496305', 1, '2020-01-10 00:00:00.000000', 'PPSD Test School', 'Something real bad', 'This is a second test', '', 0, 0, 0, 0, 1, 0, '')]
(Background on this error at: http://sqlalche.me/e/e3q8)
2020-01-13 12:35:06,855 INFO: Web CIR startup [in C:\Reports\Applications\web_CIR\app\__init__.py:47]
2020-01-13 12:36:01,608 INFO: Web CIR startup [in C:\Reports\Applications\web_CIR\app\__init__.py:47]
2020-01-13 12:36:36,084 ERROR: Exception on /CIR [POST] [in c:\reports\applications\web_cir\venv\lib\site-packages\flask\app.py:1891]
Traceback (most recent call last):
  File "c:\reports\applications\web_cir\venv\lib\site-packages\flask\app.py", line 2446, in wsgi_app
    response = self.full_dispatch_request()
  File "c:\reports\applications\web_cir\venv\lib\site-packages\flask\app.py", line 1951, in full_dispatch_request
    rv = self.handle_user_exception(e)
  File "c:\reports\applications\web_cir\venv\lib\site-packages\flask\app.py", line 1820, in handle_user_exception
    reraise(exc_type, exc_value, tb)
  File "c:\reports\applications\web_cir\venv\lib\site-packages\flask\_compat.py", line 39, in reraise
    raise value
  File "c:\reports\applications\web_cir\venv\lib\site-packages\flask\app.py", line 1949, in full_dispatch_request
    rv = self.dispatch_request()
  File "c:\reports\applications\web_cir\venv\lib\site-packages\flask\app.py", line 1935, in dispatch_request
    return self.view_functions[rule.endpoint](**req.view_args)
  File "c:\reports\applications\web_cir\venv\lib\site-packages\flask_login\utils.py", line 261, in decorated_view
    return func(*args, **kwargs)
  File "C:\Reports\Applications\web_CIR\app\routes.py", line 59, in CIR
    CIR_mail(current_user, report)
  File "C:\Reports\Applications\web_CIR\app\email.py", line 16, in CIR_mail
    recipients = school.distlist.split()
AttributeError: 'SchoolLookup' object has no attribute 'distlist'
2020-01-13 12:37:20,730 INFO: Web CIR startup [in C:\Reports\Applications\web_CIR\app\__init__.py:47]
2020-01-13 14:24:27,943 INFO: Web CIR startup [in C:\Reports\Applications\web_CIR\app\__init__.py:49]
2020-01-13 14:47:37,102 INFO: Web CIR startup [in C:\Reports\Applications\web_CIR\app\__init__.py:49]
